<?xml version="1.0" encoding="UTF-8"?>
<!-- Generated by org.testng.reporters.JUnitXMLReporter -->
<testsuite ignored="0" hostname="NGOC-THY-PC" failures="1" tests="1" name="run on firefox" time="19.119" errors="0" timestamp="08 Aug 2021 09:49:57 GMT">
  <testcase classname="com.jquery.Level_14_Assert_Verify_Custom" name="TC_01_Paging" time="3.4">
    <failure type="java.lang.Throwable" message="Multiple failures (3):
Failure 1 of 3
java.lang.AssertionError: expected [false] but found [true]
	at org.testng.Assert.fail(Assert.java:96)
	at org.testng.Assert.failNotEquals(Assert.java:776)
	at org.testng.Assert.assertFalse(Assert.java:65)
	at org.testng.Assert.assertFalse(Assert.java:75)
	at commons.BaseTest.checkFailed(BaseTest.java:105)
	at commons.BaseTest.verifyFalse(BaseTest.java:115)
	at com.jquery.Level_14_Assert_Verify_Custom.TC_01_Paging(Level_14_Assert_Verify_Custom.java:29)
	at java.base/jdk.internal.reflect.NativeMethodAccessorImpl.invoke0(Native Method)
	at java.base/jdk.internal.reflect.NativeMethodAccessorImpl.invoke(NativeMethodAccessorImpl.java:64)
	at java.base/jdk.internal.reflect.DelegatingMethodAccessorImpl.invoke(DelegatingMethodAccessorImpl.java:43)
	at java.base/java.lang.reflect.Method.invoke(Method.java:564)
	at org.testng.internal.MethodInvocationHelper.invokeMethod(MethodInvocationHelper.java:124)
	at org.testng.internal.Invoker.invokeMethod(Invoker.java:583)
	at org.testng.internal.Invoker.invokeTestMethod(Invoker.java:719)
	at org.testng.internal.Invoker.invokeTestMethods(Invoker.java:989)
	at org.testng.internal.TestMethodWorker.invokeTestMethods(TestMethodWorker.java:125)
	at org.testng.internal.TestMethodWorker.run(TestMethodWorker.java:109)
	at org.testng.TestRunner.privateRun(TestRunner.java:648)
	at org.testng.TestRunner.run(TestRunner.java:505)
	at org.testng.SuiteRunner.runTest(SuiteRunner.java:455)
	at org.testng.SuiteRunner.runSequentially(SuiteRunner.java:450)
	at org.testng.SuiteRunner.privateRun(SuiteRunner.java:415)
	at org.testng.SuiteRunner.run(SuiteRunner.java:364)
	at org.testng.SuiteRunnerWorker.runSuite(SuiteRunnerWorker.java:52)
	at org.testng.SuiteRunnerWorker.run(SuiteRunnerWorker.java:84)
	at org.testng.TestNG.runSuitesSequentially(TestNG.java:1208)
	at org.testng.TestNG.runSuitesLocally(TestNG.java:1137)
	at org.testng.TestNG.runSuites(TestNG.java:1049)
	at org.testng.TestNG.run(TestNG.java:1017)
	at org.testng.remote.AbstractRemoteTestNG.run(AbstractRemoteTestNG.java:115)
	at org.testng.remote.RemoteTestNG.initAndRun(RemoteTestNG.java:251)
	at org.testng.remote.RemoteTestNG.main(RemoteTestNG.java:77)

Failure 2 of 3
java.lang.AssertionError: expected [false] but found [true]
	at org.testng.Assert.fail(Assert.java:96)
	at org.testng.Assert.failNotEquals(Assert.java:776)
	at org.testng.Assert.assertFalse(Assert.java:65)
	at org.testng.Assert.assertFalse(Assert.java:75)
	at commons.BaseTest.checkFailed(BaseTest.java:105)
	at commons.BaseTest.verifyFalse(BaseTest.java:115)
	at com.jquery.Level_14_Assert_Verify_Custom.TC_01_Paging(Level_14_Assert_Verify_Custom.java:32)
	at java.base/jdk.internal.reflect.NativeMethodAccessorImpl.invoke0(Native Method)
	at java.base/jdk.internal.reflect.NativeMethodAccessorImpl.invoke(NativeMethodAccessorImpl.java:64)
	at java.base/jdk.internal.reflect.DelegatingMethodAccessorImpl.invoke(DelegatingMethodAccessorImpl.java:43)
	at java.base/java.lang.reflect.Method.invoke(Method.java:564)
	at org.testng.internal.MethodInvocationHelper.invokeMethod(MethodInvocationHelper.java:124)
	at org.testng.internal.Invoker.invokeMethod(Invoker.java:583)
	at org.testng.internal.Invoker.invokeTestMethod(Invoker.java:719)
	at org.testng.internal.Invoker.invokeTestMethods(Invoker.java:989)
	at org.testng.internal.TestMethodWorker.invokeTestMethods(TestMethodWorker.java:125)
	at org.testng.internal.TestMethodWorker.run(TestMethodWorker.java:109)
	at org.testng.TestRunner.privateRun(TestRunner.java:648)
	at org.testng.TestRunner.run(TestRunner.java:505)
	at org.testng.SuiteRunner.runTest(SuiteRunner.java:455)
	at org.testng.SuiteRunner.runSequentially(SuiteRunner.java:450)
	at org.testng.SuiteRunner.privateRun(SuiteRunner.java:415)
	at org.testng.SuiteRunner.run(SuiteRunner.java:364)
	at org.testng.SuiteRunnerWorker.runSuite(SuiteRunnerWorker.java:52)
	at org.testng.SuiteRunnerWorker.run(SuiteRunnerWorker.java:84)
	at org.testng.TestNG.runSuitesSequentially(TestNG.java:1208)
	at org.testng.TestNG.runSuitesLocally(TestNG.java:1137)
	at org.testng.TestNG.runSuites(TestNG.java:1049)
	at org.testng.TestNG.run(TestNG.java:1017)
	at org.testng.remote.AbstractRemoteTestNG.run(AbstractRemoteTestNG.java:115)
	at org.testng.remote.RemoteTestNG.initAndRun(RemoteTestNG.java:251)
	at org.testng.remote.RemoteTestNG.main(RemoteTestNG.java:77)

Failure 3 of 3
java.lang.AssertionError: expected [false] but found [true]">
      <![CDATA[java.lang.Throwable: Multiple failures (3):
Failure 1 of 3
java.lang.AssertionError: expected [false] but found [true]
at commons.BaseTest.checkFailed(BaseTest.java:105)
at commons.BaseTest.verifyFalse(BaseTest.java:115)
at com.jquery.Level_14_Assert_Verify_Custom.TC_01_Paging(Level_14_Assert_Verify_Custom.java:29)

Failure 2 of 3
java.lang.AssertionError: expected [false] but found [true]
at commons.BaseTest.checkFailed(BaseTest.java:105)
at commons.BaseTest.verifyFalse(BaseTest.java:115)
at com.jquery.Level_14_Assert_Verify_Custom.TC_01_Paging(Level_14_Assert_Verify_Custom.java:32)

Failure 3 of 3
java.lang.AssertionError: expected [false] but found [true]
at commons.BaseTest.checkFailed(BaseTest.java:105)
at commons.BaseTest.verifyFalse(BaseTest.java:115)
at com.jquery.Level_14_Assert_Verify_Custom.TC_01_Paging(Level_14_Assert_Verify_Custom.java:38)
... Removed 87 stack frames]]>
    </failure>
  </testcase> <!-- TC_01_Paging -->
</testsuite> <!-- run on firefox -->
